<?xml version="1.0" ?>
<!-- =================================================================================== -->
<!-- |    This document was autogenerated by xacro from /home/kika/phd/rnf2021/ros_ws/src/exoskeleton_ros/exoskeleton_description/urdf/exo_left.urdf.xacro | -->
<!-- |    EDITING THIS FILE BY HAND IS NOT RECOMMENDED                                 | -->
<!-- =================================================================================== -->
<robot name="exo_left">
  <material name="Black">
    <color rgba="0.0 0.0 0.0 1.0"/>
  </material>
  <material name="Blue">
    <color rgba="0.0 0.0 0.8 1.0"/>
  </material>
  <material name="Green">
    <color rgba="0.0 0.8 0.0 1.0"/>
  </material>
  <material name="Grey">
    <color rgba="0.4 0.4 0.4 1.0"/>
  </material>
  <material name="Orange">
    <color rgba="1.0 0.4235294117647059 0.0392156862745098 1.0"/>
  </material>
  <material name="Brown">
    <color rgba="0.8705882352941177 0.8117647058823529 0.7647058823529411 1.0"/>
  </material>
  <material name="Red">
    <color rgba="0.8 0.0 0.0 1.0"/>
  </material>
  <material name="White">
    <color rgba="1.0 1.0 1.0 1.0"/>
  </material>
  <material name="Silver">
    <color rgba="1.0 1.0 1.0 1.0"/>
  </material>
  <!-- Fix to world -->
  <link name="world"/>
  <!-- Connection joint -->
  <joint name="world_exo_joint" type="fixed">
    <origin rpy="0 0 0" xyz="0 0 0"/>
    <parent link="world"/>
    <child link="exo_link_0"/>
  </joint>
  <link name="exo_link_0">
    <inertial>
      <origin rpy="0 0 0" xyz="0 0 0"/>
      <mass value="1"/>
      <inertia ixx="1.0" ixy="0.0" ixz="0.0" iyy="1.0" iyz="0.0" izz="1.0"/>
    </inertial>
    <visual>
      <origin rpy="0 0 0" xyz="-0.1 -0.05 -0.05"/>
      <geometry>
        <mesh filename="package://exoskeleton_description/meshes/base_short.stl" scale="0.01 0.01 0.01"/>
        <material>
          <color rgba="1 0 0 1"/>
        </material>
      </geometry>
    </visual>
  </link>
  <joint name="exo_joint_1" type="revolute">
    <origin rpy="0 3.1415 0" xyz="-0.1 0 0"/>
    <parent link="exo_link_0"/>
    <child link="exo_link_1"/>
    <axis xyz="0 0 1"/>
    <limit effort="300" lower="-2.9670597283903604" upper="2.9670597283903604" velocity="10"/>
    <dynamics damping="0.4" friction="0.4"/>
  </joint>
  <link name="exo_link_1">
    <inertial>
      <origin rpy="0 0 0" xyz="0.5 0 0"/>
      <mass value="1"/>
      <inertia ixx="1.0" ixy="0.0" ixz="0.0" iyy="0.0" iyz="0.0" izz="1.0"/>
    </inertial>
    <visual>
      <origin rpy="0 0 0" xyz="0.1 -0.05 -0.05"/>
      <geometry>
        <mesh filename="package://exoskeleton_description/meshes/link.stl" scale="0.01 0.01 0.01"/>
        <material>
          <color rgba="0 1 0 1"/>
        </material>
      </geometry>
    </visual>
  </link>
  <joint name="exo_joint_2" type="revolute">
    <origin rpy="0 0 0" xyz="1.15 0 -0.05"/>
    <parent link="exo_link_1"/>
    <child link="exo_link_2"/>
    <axis xyz="0 0 1"/>
    <limit effort="300" lower="-2.9670597283903604" upper="2.9670597283903604" velocity="10"/>
    <dynamics damping="0.4" friction="0.4"/>
  </joint>
  <link name="exo_link_2">
    <inertial>
      <origin rpy="0 0 0" xyz="0.5 0 0"/>
      <mass value="1"/>
      <inertia ixx="1.0" ixy="0.0" ixz="0.0" iyy="0.0" iyz="0.0" izz="1.0"/>
    </inertial>
    <visual>
      <origin rpy="0 0 0" xyz="0.05 -0.05 0"/>
      <geometry>
        <mesh filename="package://exoskeleton_description/meshes/link.stl" scale="0.01 0.01 0.01"/>
        <material>
          <color rgba="0 0 1 1"/>
        </material>
      </geometry>
    </visual>
  </link>
  <gazebo>
    <plugin filename="libgazebo_ros_control.so" name="gazebo_ros_control">
      <robotNamespace>/exo</robotNamespace>
      <!-- <robotSimType>gazebo_ros_control/DefaultRobotHWSim</robotSimType> -->
    </plugin>
  </gazebo>
  <gazebo reference="exo_base">
    <material>Gazebo/Grey</material>
    <mu1>0.4</mu1>
    <mu2>0.4</mu2>
  </gazebo>
  <gazebo reference="exo_link_0">
    <material>Gazebo/Grey</material>
    <mu1>0.4</mu1>
    <mu2>0.4</mu2>
  </gazebo>
  <gazebo reference="exo_link_1">
    <material>Gazebo/Grey</material>
    <mu1>0.4</mu1>
    <mu2>0.4</mu2>
  </gazebo>
  <gazebo reference="exo_link_2">
    <material>Gazebo/Grey</material>
    <mu1>0.4</mu1>
    <mu2>0.4</mu2>
  </gazebo>
  <transmission name="exo_tran_1">
    <robotNamespace>/exo</robotNamespace>
    <type>transmission_interface/SimpleTransmission</type>
    <joint name="exo_joint_1">
      <hardwareInterface>hardware_interface/EffortJointInterface</hardwareInterface>
    </joint>
    <actuator name="exo_motor_1">
      <hardwareInterface>hardware_interface/EffortJointInterface</hardwareInterface>
      <mechanicalReduction>1</mechanicalReduction>
    </actuator>
  </transmission>
  <transmission name="exo_tran_2">
    <robotNamespace>/exo</robotNamespace>
    <type>transmission_interface/SimpleTransmission</type>
    <joint name="exo_joint_2">
      <hardwareInterface>hardware_interface/EffortJointInterface</hardwareInterface>
    </joint>
    <actuator name="exo_motor_2">
      <hardwareInterface>hardware_interface/EffortJointInterface</hardwareInterface>
      <mechanicalReduction>1</mechanicalReduction>
    </actuator>
  </transmission>
</robot>